<?xml version="1.0" ?>
<!--
SPDX-FileCopyrightText: Copyright (c) 2024 NVIDIA CORPORATION & AFFILIATES. All rights reserved.
SPDX-License-Identifier: Apache-2.0

Licensed under the Apache License, Version 2.0 (the "License");
you may not use this file except in compliance with the License.
You may obtain a copy of the License at

http://www.apache.org/licenses/LICENSE-2.0

Unless required by applicable law or agreed to in writing, software
distributed under the License is distributed on an "AS IS" BASIS,
WITHOUT WARRANTIES OR CONDITIONS OF ANY KIND, either express or implied.
See the License for the specific language governing permissions and
limitations under the License.
-->

<!-- Robot with all joint types, intended for testing kinematics. -->
<robot name="joint_venture">
    <link name="base"/>
    <link name="link0"/>
    <link name="link1"/>
    <link name="link2"/>
    <link name="link3"/>
    <link name="link4"/>
    <link name="link5"/>
    <link name="link6"/>
    <link name="link7"/>
    <link name="link8"/>
    <link name="link9"/>
    <link name="link10"/>
    <link name="link11"/>
    <link name="link12"/>
    <link name="link13"/>
    <link name="link14"/>
    <link name="link15"/>

    <joint name="positive_x_prismatic" type="prismatic">
        <parent link="base"/>
        <child link="link0"/>
        <origin rpy="4.32 -0.96 0.25" xyz="-0.85 0.32 0.72"/>
        <axis xyz="1 0 0"/>
        <limit effort="100" lower="-100.0" upper="100.0" velocity="100"/>
    </joint>
    <joint name="positive_y_prismatic" type="prismatic">
        <parent link="link0"/>
        <child link="link1"/>
        <origin rpy="-3.14 1.59 -5.80" xyz="0.67 -0.44 0.29"/>
        <axis xyz="0 1 0"/>
        <limit effort="100" lower="-100.0" upper="100.0" velocity="100"/>
    </joint>
    <joint name="positive_z_prismatic" type="prismatic">
        <parent link="link1"/>
        <child link="link2"/>
        <origin rpy="1.75 -3.13 5.73" xyz="-0.23 0.91 -0.49"/>
        <axis xyz="0 0 1"/>
        <limit effort="100" lower="-100.0" upper="100.0" velocity="100"/>
    </joint>
    <joint name="negative_x_prismatic" type="prismatic">
        <parent link="link2"/>
        <child link="link3"/>
        <origin rpy="-4.79 2.46 -2.12" xyz="0.55 -0.37 0.67"/>
        <axis xyz="-1 0 0"/>
        <limit effort="100" lower="-100.0" upper="100.0" velocity="100"/>
    </joint>
    <joint name="negative_y_prismatic" type="prismatic">
        <parent link="link3"/>
        <child link="link4"/>
        <origin rpy="6.12 -1.92 3.99" xyz="-0.14 0.88 0.45"/>
        <axis xyz="0 -1 0"/>
        <limit effort="100" lower="-100.0" upper="100.0" velocity="100"/>
    </joint>
    <joint name="negative_z_prismatic" type="prismatic">
        <parent link="link4"/>
        <child link="link5"/>
        <origin rpy="0.28 5.18 -1.45" xyz="0.81 -0.61 -0.75"/>
        <axis xyz="0 0 -1"/>
        <limit effort="100" lower="-100.0" upper="100.0" velocity="100"/>
    </joint>
    <joint name="arbitrary_prismatic" type="prismatic">
        <parent link="link5"/>
        <child link="link6"/>
        <origin rpy="-1.60 2.78 -0.94" xyz="0.39 -0.80 0.23"/>
        <axis xyz="0.2 -0.3 0.6"/>
        <limit effort="100" lower="-100.0" upper="100.0" velocity="100"/>
    </joint>
    <joint name="fixed_intermediate" type="fixed">
        <parent link="link6"/>
        <child link="link7"/>
        <origin rpy="4.66 -5.03 1.79" xyz="-0.49 0.58 -0.19"/>
    </joint>
    <joint name="positive_x_revolute" type="revolute">
        <parent link="link7"/>
        <child link="link8"/>
        <origin rpy="-3.34 0.64 -4.11" xyz="0.14 -0.32 0.92"/>
        <axis xyz="1 0 0"/>
        <limit effort="100" lower="-100.0" upper="100.0" velocity="100"/>
    </joint>
    <joint name="positive_y_revolute" type="revolute">
        <parent link="link8"/>
        <child link="link9"/>
        <origin rpy="2.21 -2.56 5.99" xyz="-0.91 0.12 -0.55"/>
        <axis xyz="0 1 0"/>
        <limit effort="100" lower="-100.0" upper="100.0" velocity="100"/>
    </joint>
    <joint name="positive_z_revolute" type="revolute">
        <parent link="link9"/>
        <child link="link10"/>
        <origin rpy="-4.66 -2.11 -3.89" xyz="-0.29 0.81 -0.48"/>
        <axis xyz="0 0 1"/>
        <limit effort="100" lower="-100.0" upper="100.0" velocity="100"/>
    </joint>
    <joint name="negative_x_revolute" type="revolute">
        <parent link="link10"/>
        <child link="link11"/>
        <origin rpy="3.45 -1.22 4.56" xyz="0.45 -0.67 0.21"/>
        <axis xyz="-1 0 0"/>
        <limit effort="100" lower="-100.0" upper="100.0" velocity="100"/>
    </joint>
    <joint name="negative_y_revolute" type="revolute">
        <parent link="link11"/>
        <child link="link12"/>
        <origin rpy="2.10 0.98 -1.23" xyz="-0.12 0.57 -0.36"/>
        <axis xyz="0 -1 0"/>
        <limit effort="100" lower="-100.0" upper="100.0" velocity="100"/>
    </joint>
    <joint name="negative_z_revolute" type="revolute">
        <parent link="link12"/>
        <child link="link13"/>
        <origin rpy="-0.67 4.23 -2.99" xyz="0.71 -0.13 0.45"/>
        <axis xyz="0 0 -1"/>
        <limit effort="100" lower="-100.0" upper="100.0" velocity="100"/>
    </joint>
    <joint name="arbitrary_revolute" type="revolute">
        <parent link="link13"/>
        <child link="link14"/>
        <origin rpy="5.78 -3.56 0.87" xyz="-0.48 0.65 -0.73"/>
        <axis xyz="-0.7 0.4 -0.1"/>
        <limit effort="100" lower="-100.0" upper="100.0" velocity="100"/>
    </joint>
    <joint name="fixed_final" type="fixed">
        <parent link="link14"/>
        <child link="link15"/>
        <origin rpy="-2.34 1.45 -3.67" xyz="0.56 -0.77 0.23"/>
    </joint>
</robot>
